<?xml version="1.0"?>
<robot name="simple_1dof">

    <link name="world">
    </link> 
    
    <joint name="dummy_base" type="fixed">
        <origin xyz="0 0 0" rpy="0 0 0"/>
        <parent link="world"/>
        <child link="cube_base"/>
    </joint>

    <link name="cube_base">
        <inertial>
            <origin xyz="0 0 0" rpy="0 0 0"/>
            <mass value="1.0"/>
            <inertia ixx="0.001" iyy="0.001" izz="0.1" ixy="0" ixz="0" iyz="0"/>
        </inertial>
        <visual>
            <origin xyz="0 0 0" rpy="0 0 0"/>
            <geometry>
				<mesh filename="package://simplecube_description/meshes/qb_meshes/dae/qb_base_flange_m.dae" />
            </geometry>	
        </visual> 
		<visual>
            <origin xyz="0 0 0" rpy="0 0 0"/>
            <geometry>
				<mesh filename="package://simplecube_description/meshes/qb_meshes/dae/qbmove_frame_m.dae" />
            </geometry>	
        </visual>
        <collision>
            <origin xyz="0 0 0" rpy="0 0 0"/>
            <geometry>
                <mesh filename="package://simplecube_description/meshes/qb_meshes/stl/qbmove_frame_m.stl" />
            </geometry> 
        </collision>
        <collision>
            <origin xyz="0 0 0" rpy="0 0 0"/>
            <geometry>
                <mesh filename="package://simplecube_description/meshes/qb_meshes/stl/qb_base_flange_m.stl" />
            </geometry> 
        </collision>
    </link>

    <joint name="joint" type="revolute">
        <origin xyz="0 0 0.033" rpy="0 0 0"/>
        <parent link="cube_base"/>
        <child link="link"/>
		<limit effort="300" velocity="100" lower="-3.14" upper="3.14" />
        <axis xyz="0 0 1"/>
        <dynamics damping="0.1" friction="0.0" />
    </joint>

    <link name="link"> 
        <inertial>
            <origin xyz="-0.035 0 0.038" rpy="0 0 0"/>
            <!--origin xyz="0 0 0" rpy="0 0 0"/-->
            <mass value="0.20"/>
            <inertia ixx="0.001" iyy="0.001" izz="0.001" ixy="0" ixz="0" iyz="0"/>
        </inertial>	
        <visual>
            <origin xyz="0 0 0.022" rpy="1.57 0 0"/>
            <!--origin xyz="0 0 0.022" rpy="1.57 0 0"/-->
            <geometry>
                <mesh filename="package://simplecube_description/meshes/qb_meshes/dae/qbmove_pulley_m.dae" />
            </geometry>		
        </visual>
		<visual>
            <origin xyz="-0.035 0 0.038" rpy="0 0 0"/>
            <!--origin xyz="0 0 0" rpy="0 0 0"/-->
            <geometry>
                <mesh filename="package://simplecube_description/meshes/onedof/dae/demoshaft.dae" />
            </geometry>		
        </visual>
        <collision>
            <origin xyz="-0.035 0 0.038" rpy="0 0 0"/>
            <!--origin xyz="0 0 0" rpy="0 0 0"/-->
            <geometry>
                <mesh filename="package://simplecube_description/meshes/onedof/demoshaft.stl" />
            </geometry> 
        </collision>
    </link>  

    <gazebo>
        <self_collide>1</self_collide>
    </gazebo>

    <!--gazebo>
       <plugin name="sea_j1" filename="libsea_plugin.so">
           <joint>J1</joint>
           <namespace>simple_1dof</namespace>
           <stiffness>1</stiffness>
           <pub_eltau>false</pub_eltau>
           <pub_state>true</pub_state>
           <sub_ext_tau>false</sub_ext_tau>
       </plugin>
    </gazebo-->
     <!--gazebo>
         <plugin name="advanced_vsa_j1" filename="libadvanced_plugin.so">
             <joint>J1</joint>
             <control_type>2</control_type>
             <pub_eltau>true</pub_eltau>
             <pub_state>true</pub_state>
             <sub_ext_tau>true</sub_ext_tau>
         </plugin>
     </gazebo-->
     <!-- Legend for the libsea_plugin.so custom plugin 
    
        # The operational modes are the following
        #   [0] = LinkTorque
        #   [1] = LinkPID
        #   [2] = SpingRefs
        #   [3] = SpringEqPres
        #   [4] = MotorTorques
        #   [5] = PIDRefs
        #   [6] = PIDEqPres
    -->
    <!-- Plugin insertion -->
    <!--gazebo>
        <plugin name="sea_j1" filename="libsea_plugin.so">
            
            <joint>J1</joint>
            <operation_mode>4</operation_mode>
            <pub_eltau>true</pub_eltau>
            <pub_state>true</pub_state>
            <sub_ext_tau>true</sub_ext_tau>
            
            
            <spring_k1>0.002</spring_k1>
            <max_def>0.8</max_def>
            
            <mot_J>0.009</mot_J>  
            <mot_D>0.002</mot_1_D>
            <mot_1_tauMax>20.0</mot_1_tauMax>
            <mot_1_maxVel>30.0</mot_1_maxVel>
            <mot_1_minPos>-inf</mot_1_minPos>
            <mot_1_maxPos>inf</mot_1_maxPos>
            <mot_1_tauFric>0.0</mot_1_tauFric>
        </plugin>
    </gazebo-->
    
    <!-- Plugin insertion -->
    <gazebo>
        <plugin name="sea_j" filename="libsea_plugin.so">
            # REQUIRED tags
            <joint>joint</joint>
            <operation_mode>4</operation_mode>     # select the operational mode (see above)
            <pub_eltau>true</pub_eltau>            # enable elastic torques publishing
            <pub_state>true</pub_state>            # enable link state publishing
            <sub_ext_tau>true</sub_ext_tau>        # enable subscription to external torques
            
            # Available OPTIONAL tags with default values are
            <!-- spring parameters -->
            <spring_k>10</spring_k>
            <max_def>5.0</max_def>
            <!-- motors parameters -->
            <mot_J>0.1</mot_J>                   # motor inertia
            <mot_D>0.2</mot_D>                   # motor damping
            <mot_tauMax>6.0</mot_tauMax>            # maximum motor torque
            <mot_maxVel>6.0</mot_maxVel>            # maximum motor velocity
            <mot_minPos>-10</mot_minPos>           # minimum motor position
            <mot_maxPos>10</mot_maxPos>            # maximum motor position
            <mot_tauFric>0.1</mot_tauFric>          # static motor friction 
        </plugin>
    </gazebo>

</robot>
