<?xml version="1.0"?>
<robot name="simpleCube">

    <link name="world">
    </link> 
    
    <joint name="dummy_base" type="floating">
        <origin xyz="0 0 0" rpy="0 0 0"/>
        <parent link="world"/>
        <child link="cube_base"/>
    </joint>

    <link name="cube_base">
        <inertial>
            <origin xyz="0 0 0" rpy="0 0 0"/>
            <mass value="1.0"/>
            <inertia ixx="0.001" iyy="0.001" izz="0.001" ixy="0" ixz="0" iyz="0"/>
        </inertial>
        <visual>
            <origin xyz="0 0 0" rpy="0 0 0"/>
            <geometry>
				<mesh filename="package://simplecube_description/meshes/qb_meshes/dae/qb_base_flange_m.dae" />
            </geometry>	
        </visual> 
		<visual>
            <origin xyz="0 0 0" rpy="0 0 0"/>
            <geometry>
				<mesh filename="package://simplecube_description/meshes/qb_meshes/dae/qbmove_frame_m.dae" />
            </geometry>	
        </visual>
        <collision>
            <origin xyz="0 0 0" rpy="0 0 0"/>
            <geometry>
                <mesh filename="package://simplecube_description/meshes/qb_meshes/stl/qbmove_frame_m.stl" />
            </geometry> 
        </collision>
        <collision>
            <origin xyz="0 0 0" rpy="0 0 0"/>
            <geometry>
                <mesh filename="package://simplecube_description/meshes/qb_meshes/stl/qb_base_flange_m.stl" />
            </geometry> 
        </collision>
    </link>

    <joint name="J1" type="revolute">
        <origin xyz="0 0 0.033" rpy="0 0 0"/>
        <parent link="cube_base"/>
        <child link="Link1"/>
		<limit effort="300" velocity="100" lower="-3.14" upper="3.14" />
        <axis xyz="0 0 1"/>
        <dynamics damping="0.2"/>
    </joint>

    <link name="Link1"> 
        <inertial>
            <origin xyz="-0.035 0 0.038" rpy="0 0 0"/>
            <mass value="0.20"/>
            <inertia ixx="0.001" iyy="0.001" izz="0.001" ixy="0" ixz="0" iyz="0"/>
        </inertial>	
        <visual>
            <origin xyz="0 0 0.022" rpy="1.57 0 0"/>
            <geometry>
                <mesh filename="package://simplecube_description/meshes/qb_meshes/dae/qbmove_pulley_m.dae" />
            </geometry>		
        </visual>
		<visual>
            <origin xyz="-0.035 0 0.038" rpy="0 0 0"/>
            <geometry>
                <mesh filename="package://simplecube_description/meshes/onedof/dae/demoshaft.dae" />
            </geometry>		
        </visual>
        <collision>
            <origin xyz="-0.035 0 0.038" rpy="0 0 0"/>
            <geometry>
                <mesh filename="package://simplecube_description/meshes/onedof/demoshaft.stl" />
            </geometry> 
        </collision>
    </link>  

    <gazebo>
        <self_collide>1</self_collide>
    </gazebo>
    
     <gazebo>
         <plugin name="sea_j1" filename="libsea_plugin.so">
             <joint>J1</joint>
             <namespace>your_ns</namespace>
             <stiffness>0.1</stiffness>
             <pub_state>true</pub_state>
             <sub_ext_tau>true</sub_ext_tau>
         </plugin>
    </gazebo>

    <!-- Plugin insertion -->
    <gazebo>
        <plugin name="sea_j1" filename="libsea_plugin.so">
            # REQUIRED tags
            <joint>J1</joint>
            <operation_mode>4</operation_mode>     # select the operational mode (see above)
            <pub_eltau>true</pub_eltau>            # enable elastic torques publishing
            <pub_state>true</pub_state>            # enable link state publishing
            <sub_ext_tau>true</sub_ext_tau>        # enable subscription to external torques
            
            # Available OPTIONAL tags with default values are
            <!-- spring parameters -->
            <spring_k>10.0</spring_k>
            <max_def>3.15</max_def>
            <!-- motors parameters -->
            <mot_J>0.0233</mot_J>                   # motor inertia
            <mot_D>0.19</mot_D>                     # motor damping
            <mot_tauMax>6.0</mot_tauMax>            # maximum motor torque
            <mot_maxVel>6.0</mot_maxVel>            # maximum motor velocity
            <mot_minPos>-100</mot_minPos>           # minimum motor position
            <mot_maxPos>100</mot_maxPos>            # maximum motor position
            <mot_tauFric>0.0</mot_tauFric>          # static motor friction 
            <!-- controllers parameters -->
            <ctrl_P>125</ctrl_P>                    # proportional gain on motor
            <ctrl_I>0</ctrl_I>                      # integral gain on motor
            <ctrl_D>4.5</ctrl_D>                     # derivative gain on motor
        </plugin>
    </gazebo>
</robot>
